Workbook

Sheet Inputs
A1: B&P | ASCE 7-22 SEISMIC ELF INPUTS (PRELIMINARY)
A4: PARAMETER | B4: VALUE | C4: UNITS | D4: SOURCE / NOTE
A5: Project number | B5: HACKATHON-001 | D5: User or Part 1
A6: ASCE 7 edition | B6: 7-22 | D6: Part 3 supports ASCE 7-22 only
A7: Hazard data status | B7: SYNTHETIC_DEMO | D7: API retrieval is not verification
A8: Engineer reviewed input? | B8: NO | D8: Explicit confirmation
A9: SDS | B9: ='Imported ASCE'!B19 -> 0.85 | C9: g | D9: Linked to Imported ASCE (green)
A10: SD1 | B10: ='Imported ASCE'!B20 -> 0.55 | C10: g | D10: Linked to Imported ASCE (green)
A11: S1 | B11: ='Imported ASCE'!B18 -> 0.45 | C11: g | D11: Linked to Imported ASCE (green)
A12: TL | B12: ='Imported ASCE'!B21 -> 8 | C12: sec | D12: Linked to Imported ASCE (green)
A13: Risk Category | B13: II | D13: I / II / III / IV - sets Ie and SDC
A14: Site Class | B14: D | D14: Used for 12.8.1.3 check
A15: Part 1 reported SDC | B15: D | D15: Compared with computed SDC
A16: Structural height hn | B16: 60 | C16: ft | D16: Engineer
A17: Stories above base | B17: 4 | D17: Engineer (12.8.1.3 only)
A18: W - effective seismic weight | B18: 1500 | C18: kips | D18: Engineer supplied; not calculated
A19: Apply Section 12.8.1.3 max SDS? | B19: NO | D19: YES / NO
A20: Confirm: regular, no irregularities | B20: NO | D20: Engineer confirmation (not checked)
A21: Confirm: rho = 1.0 | B21: NO | D21: Engineer confirmation (not checked)
A23: DIRECTION INPUTS | B23: X | C23: Y | D23: NOTE
A24: Combination | B24: single | C24: single | D24: single / horizontal / vertical (12.2.3)
A25: System 1 ID (Table 12.2-1) | B25: C1 | C25: B2 | D25: Vertical: System 1 = UPPER, System 2 = LOWER
A26: System 2 ID (Table 12.2-1)
A27: System 3 ID (Table 12.2-1)
A28: System 4 ID (Table 12.2-1)
A29: Analysis period T (blank = use Ta) | B29: 1.2 | D29: sec
A30: Table 12.8-2 structure type key | B30: steel_mf | C30: all_other | D30: See Code Tables A11:A15

Sheet Cs & Base Shear
A1: B&P | SEISMIC Cs & BASE SHEAR - X / Y
A4: GLOBAL | B4: VALUE | D4: UNITS | E4: FORMULA / REFERENCE
A5: Ie | B5: =INDEX('Code Tables'!$B$5:$B$8,MATCH(Inputs!$B$13,'Code Tables'!$A$5:$A$8,0)) -> 1 | E5: Table 1.5-2
A6: SDC from SDS | B6: =IF(Inputs!$B$9>=0.5,"D",IF(Inputs!$B$9>=0.33,IF(Inputs!$B$13="IV","D","C"),IF(Inputs!$B$9>=0.167,IF(Inputs!$B$13="IV","C","B"),"A"))) | E6: Table 11.6-1
A7: SDC from SD1 | B7: =IF(Inputs!$B$10>=0.2,"D",IF(Inputs!$B$10>=0.133,IF(Inputs!$B$13="IV","D","C"),IF(Inputs!$B$10>=0.067,IF(Inputs!$B$13="IV","C","B"),"A"))) | E7: Table 11.6-2
A8: SDC (governing) | B8: =IF(Inputs!$B$11>=0.75,IF(Inputs!$B$13="IV","F","E"),IF(MATCH(B6,{"A","B","C","D","E","F"},0)>=MATCH(B7,{"A","B","C","D","E","F"},0),B6,B7)) | E8: Section 11.6; 11.6 exception NOT applied
A9: SDC check vs Part 1 | B9: =IF(Inputs!$B$15="","No Part 1 SDC",IF(Inputs!$B$15=B8,"Matches Part 1","MISMATCH - resolve")) | E9: Warning only
A10: Cu | B10: =IF(Inputs!$B$10>='Code Tables'!$A$23,'Code Tables'!$B$23,IF(Inputs!$B$10>='Code Tables'!$A$24,'Code Tables'!$B$24+('Code Tables'!$B$23-'Code Tables'!$B$24)*(Inputs!$B$10-'Code Tables'!$A$24)/('Code Tables'!$A$23-'Code Tables'!$A$24),IF(Inputs!$B$10>='Code Tables'!$A$25,'Code Tables'!$B$25+('Code Tables'!$B$24-'Code Tables'!$B$25)*(Inputs!$B$10-'Code Tables'!$A$25)/('Code Tables'!$A$24-'Code Tables'!$A$25),IF(Inputs!$B$10>'Code Tables'!$A$26,'Code Tables'!$B$26+('Code Tables'!$B$25-'Code Tables'!$B$26)*(Inputs!$B$10-'Code Tables'!$A$26)/('Code Tables'!$A$25-'Code Tables'!$A$26),'Code Tables'!$B$26)))) -> 1.4 | E10: Table 12.8-1 (interpolated)
A11: Ts = SD1/SDS | B11: =IF(Inputs!$B$9>0,Inputs!$B$10/Inputs!$B$9,"") -> 0.64705882 | D11: sec | E11: Section 11.4
A13: BY DIRECTION | B13: X | C13: Y | D13: UNITS | E13: FORMULA / REFERENCE
A14: System 1 ID | B14: =IF(Inputs!B$25="","",Inputs!B$25) | C14: =IF(Inputs!C$25="","",Inputs!C$25) | E14: Inputs
A15: System 1 R | B15: =IF(B14="","",INDEX('Table 12.2-1'!$F:$F,MATCH(B14,'Table 12.2-1'!$A:$A,0))) -> 8 | C15: =IF(C14="","",INDEX('Table 12.2-1'!$F:$F,MATCH(C14,'Table 12.2-1'!$A:$A,0))) -> 6 | E15: Table 12.2-1
A16: System 1 Omega0 | B16: =IF(B14="","",INDEX('Table 12.2-1'!$G:$G,MATCH(B14,'Table 12.2-1'!$A:$A,0))) -> 3 | C16: =IF(C14="","",INDEX('Table 12.2-1'!$G:$G,MATCH(C14,'Table 12.2-1'!$A:$A,0))) -> 2 | E16: Table 12.2-1
A17: System 1 Cd | B17: =IF(B14="","",INDEX('Table 12.2-1'!$H:$H,MATCH(B14,'Table 12.2-1'!$A:$A,0))) -> 5.5 | C17: =IF(C14="","",INDEX('Table 12.2-1'!$H:$H,MATCH(C14,'Table 12.2-1'!$A:$A,0))) -> 5 | E17: Table 12.2-1
A18: System 1 height limit at SDC | B18: =IF(OR(B14="",$B$8="A"),"",INDEX('Table 12.2-1'!$I:$M,MATCH(B14,'Table 12.2-1'!$A:$A,0),MATCH($B$8,{"B","C","D","E","F"},0))) | C18: =IF(OR(C14="",$B$8="A"),"",INDEX('Table 12.2-1'!$I:$M,MATCH(C14,'Table 12.2-1'!$A:$A,0),MATCH($B$8,{"B","C","D","E","F"},0))) -> 160 | D18: ft | E18: Table 12.2-1 (NL/NP)
A19: System 1 limit status | B19: =IF(B18="","",IF(B18="NP","NOT PERMITTED",IF(B18="NL","OK",IF(Inputs!$B$16>B18,"EXCEEDS LIMIT","OK")))) | C19: =IF(C18="","",IF(C18="NP","NOT PERMITTED",IF(C18="NL","OK",IF(Inputs!$B$16>C18,"EXCEEDS LIMIT","OK")))) | E19: Warning only; 12.2.5.4 not evaluated
A20: System 2 ID | B20: =IF(Inputs!B$26="","",Inputs!B$26) | C20: =IF(Inputs!C$26="","",Inputs!C$26) | E20: Inputs
A21: System 2 R | B21: =IF(B20="","",INDEX('Table 12.2-1'!$F:$F,MATCH(B20,'Table 12.2-1'!$A:$A,0))) | C21: =IF(C20="","",INDEX('Table 12.2-1'!$F:$F,MATCH(C20,'Table 12.2-1'!$A:$A,0))) | E21: Table 12.2-1
A22: System 2 Omega0 | B22: =IF(B20="","",INDEX('Table 12.2-1'!$G:$G,MATCH(B20,'Table 12.2-1'!$A:$A,0))) | C22: =IF(C20="","",INDEX('Table 12.2-1'!$G:$G,MATCH(C20,'Table 12.2-1'!$A:$A,0))) | E22: Table 12.2-1
A23: System 2 Cd | B23: =IF(B20="","",INDEX('Table 12.2-1'!$H:$H,MATCH(B20,'Table 12.2-1'!$A:$A,0))) | C23: =IF(C20="","",INDEX('Table 12.2-1'!$H:$H,MATCH(C20,'Table 12.2-1'!$A:$A,0))) | E23: Table 12.2-1
A24: System 2 height limit at SDC | B24: =IF(OR(B20="",$B$8="A"),"",INDEX('Table 12.2-1'!$I:$M,MATCH(B20,'Table 12.2-1'!$A:$A,0),MATCH($B$8,{"B","C","D","E","F"},0))) | C24: =IF(OR(C20="",$B$8="A"),"",INDEX('Table 12.2-1'!$I:$M,MATCH(C20,'Table 12.2-1'!$A:$A,0),MATCH($B$8,{"B","C","D","E","F"},0))) | D24: ft | E24: Table 12.2-1 (NL/NP)
A25: System 2 limit status | B25: =IF(B24="","",IF(B24="NP","NOT PERMITTED",IF(B24="NL","OK",IF(Inputs!$B$16>B24,"EXCEEDS LIMIT","OK")))) | C25: =IF(C24="","",IF(C24="NP","NOT PERMITTED",IF(C24="NL","OK",IF(Inputs!$B$16>C24,"EXCEEDS LIMIT","OK")))) | E25: Warning only; 12.2.5.4 not evaluated
A26: System 3 ID | B26: =IF(Inputs!B$27="","",Inputs!B$27) | C26: =IF(Inputs!C$27="","",Inputs!C$27) | E26: Inputs
A27: System 3 R | B27: =IF(B26="","",INDEX('Table 12.2-1'!$F:$F,MATCH(B26,'Table 12.2-1'!$A:$A,0))) | C27: =IF(C26="","",INDEX('Table 12.2-1'!$F:$F,MATCH(C26,'Table 12.2-1'!$A:$A,0))) | E27: Table 12.2-1
A28: System 3 Omega0 | B28: =IF(B26="","",INDEX('Table 12.2-1'!$G:$G,MATCH(B26,'Table 12.2-1'!$A:$A,0))) | C28: =IF(C26="","",INDEX('Table 12.2-1'!$G:$G,MATCH(C26,'Table 12.2-1'!$A:$A,0))) | E28: Table 12.2-1
A29: System 3 Cd | B29: =IF(B26="","",INDEX('Table 12.2-1'!$H:$H,MATCH(B26,'Table 12.2-1'!$A:$A,0))) | C29: =IF(C26="","",INDEX('Table 12.2-1'!$H:$H,MATCH(C26,'Table 12.2-1'!$A:$A,0))) | E29: Table 12.2-1
A30: System 3 height limit at SDC | B30: =IF(OR(B26="",$B$8="A"),"",INDEX('Table 12.2-1'!$I:$M,MATCH(B26,'Table 12.2-1'!$A:$A,0),MATCH($B$8,{"B","C","D","E","F"},0))) | C30: =IF(OR(C26="",$B$8="A"),"",INDEX('Table 12.2-1'!$I:$M,MATCH(C26,'Table 12.2-1'!$A:$A,0),MATCH($B$8,{"B","C","D","E","F"},0))) | D30: ft | E30: Table 12.2-1 (NL/NP)
A31: System 3 limit status | B31: =IF(B30="","",IF(B30="NP","NOT PERMITTED",IF(B30="NL","OK",IF(Inputs!$B$16>B30,"EXCEEDS LIMIT","OK")))) | C31: =IF(C30="","",IF(C30="NP","NOT PERMITTED",IF(C30="NL","OK",IF(Inputs!$B$16>C30,"EXCEEDS LIMIT","OK")))) | E31: Warning only; 12.2.5.4 not evaluated
A32: System 4 ID | B32: =IF(Inputs!B$28="","",Inputs!B$28) | C32: =IF(Inputs!C$28="","",Inputs!C$28) | E32: Inputs
A33: System 4 R | B33: =IF(B32="","",INDEX('Table 12.2-1'!$F:$F,MATCH(B32,'Table 12.2-1'!$A:$A,0))) | C33: =IF(C32="","",INDEX('Table 12.2-1'!$F:$F,MATCH(C32,'Table 12.2-1'!$A:$A,0))) | E33: Table 12.2-1
A34: System 4 Omega0 | B34: =IF(B32="","",INDEX('Table 12.2-1'!$G:$G,MATCH(B32,'Table 12.2-1'!$A:$A,0))) | C34: =IF(C32="","",INDEX('Table 12.2-1'!$G:$G,MATCH(C32,'Table 12.2-1'!$A:$A,0))) | E34: Table 12.2-1
A35: System 4 Cd | B35: =IF(B32="","",INDEX('Table 12.2-1'!$H:$H,MATCH(B32,'Table 12.2-1'!$A:$A,0))) | C35: =IF(C32="","",INDEX('Table 12.2-1'!$H:$H,MATCH(C32,'Table 12.2-1'!$A:$A,0))) | E35: Table 12.2-1
A36: System 4 height limit at SDC | B36: =IF(OR(B32="",$B$8="A"),"",INDEX('Table 12.2-1'!$I:$M,MATCH(B32,'Table 12.2-1'!$A:$A,0),MATCH($B$8,{"B","C","D","E","F"},0))) | C36: =IF(OR(C32="",$B$8="A"),"",INDEX('Table 12.2-1'!$I:$M,MATCH(C32,'Table 12.2-1'!$A:$A,0),MATCH($B$8,{"B","C","D","E","F"},0))) | D36: ft | E36: Table 12.2-1 (NL/NP)
A37: System 4 limit status | B37: =IF(B36="","",IF(B36="NP","NOT PERMITTED",IF(B36="NL","OK",IF(Inputs!$B$16>B36,"EXCEEDS LIMIT","OK")))) | C37: =IF(C36="","",IF(C36="NP","NOT PERMITTED",IF(C36="NL","OK",IF(Inputs!$B$16>C36,"EXCEEDS LIMIT","OK")))) | E37: Warning only; 12.2.5.4 not evaluated
A38: R (design, base/lower system) | B38: =MIN(B15,B21,B27,B33) -> 8 | C38: =MIN(C15,C21,C27,C33) -> 6 | E38: 12.2.3: least R; vertical = MIN(upper, lower)
A39: Omega0 (design, base/lower system) | B39: =IF(Inputs!B$24="vertical",IF(B21<B15,B22,B16),MAX(IF(B15=B38,B16,0),IF(B21=B38,B22,0),IF(B27=B38,B28,0),IF(B33=B38,B34,0))) -> 3 | C39: =IF(Inputs!C$24="vertical",IF(C21<C15,C22,C16),MAX(IF(C15=C38,C16,0),IF(C21=C38,C22,0),IF(C27=C38,C28,0),IF(C33=C38,C34,0))) -> 2 | E39: 12.2.3.1 / 12.2.3.3
A40: Cd (design, base/lower system) | B40: =IF(Inputs!B$24="vertical",IF(B21<B15,B23,B17),MAX(IF(B15=B38,B17,0),IF(B21=B38,B23,0),IF(B27=B38,B29,0),IF(B33=B38,B35,0))) -> 5.5 | C40: =IF(Inputs!C$24="vertical",IF(C21<C15,C23,C17),MAX(IF(C15=C38,C17,0),IF(C21=C38,C23,0),IF(C27=C38,C29,0),IF(C33=C38,C35,0))) -> 5 | E40: 12.2.3.1 / 12.2.3.3
A41: R (upper system, vertical only) | B41: =IF(Inputs!B$24="vertical",B15,"") | C41: =IF(Inputs!C$24="vertical",C15,"") | E41: 12.2.3.1
A42: Transfer force amplification upper->lower | B42: =IF(Inputs!B$24="vertical",IF(B21<B15,B15/B21,1),"") | C42: =IF(Inputs!C$24="vertical",IF(C21<C15,C15/C21,1),"") | E42: 12.2.3.1: R_upper/R_lower if lower R is less
A43: Ct | B43: =INDEX('Code Tables'!$C$11:$C$15,MATCH(Inputs!B$30,'Code Tables'!$A$11:$A$15,0)) -> 0.028 | C43: =INDEX('Code Tables'!$C$11:$C$15,MATCH(Inputs!C$30,'Code Tables'!$A$11:$A$15,0)) -> 0.02 | E43: Table 12.8-2
...

Sheet Imported ASCE
A1: IMPORTED ASCE HAZARD EXCHANGE
A4: key | B4: value | C4: unit | D4: source
A5: schema_version | B5: BP-HZ-1 | D5: CONTRACT
A6: project_number | B6: HACKATHON-001 | D6: USER
A7: project_name | B7: FICTIONAL Hackathon Example | D7: USER
A8: address | B8: SYNTHETIC EXAMPLE; NOT A VERIFIED LOCATION | D8: USER
A9: latitude | B9: 37.77 | C9: deg | D9: USER CONFIRMED
A10: longitude | B10: -122.42 | C10: deg | D10: USER CONFIRMED
A11: asce_edition | B11: 7-22 | D11: USER
A12: risk_category | B12: II | D12: USER
A13: site_class | B13: D | D13: USER
A14: source_status | B14: SYNTHETIC_DEMO | D14: SYSTEM
A15: engineer_confirmed | B15: NO | D15: SYSTEM
A16: retrieved_utc | B16: 2026-10-27T20:00:27.884323+00:00 | D16: SYSTEM
A17: ss_g | B17: 1.15 | C17: g | D17: ASCE
A18: s1_g | B18: 0.45 | C18: g | D18: ASCE
A19: sds_g | B19: 0.85 | C19: g | D19: ASCE
A20: sd1_g | B20: 0.55 | C20: g | D20: ASCE
A21: tl_sec | B21: 8 | C21: sec | D21: ASCE
A22: sdc | B22: D | D22: ASCE
A23: wind_mph | B23: 115 | C23: mph | D23: ASCE
A24: ground_snow_psf | B24: 20 | C24: psf | D24: ASCE
A25: warnings | B25: SYNTHETIC DEMO ONLY: fictional ASCE values. NOT FOR DESIGN. | App-generated PDF; NOT the official ASCE Hazard Tool Full Report. | D25: SYSTEM

Sheet Review Notes
A1: ENGINEERING REVIEW & LIMITATIONS
A4: RESULT STATUS
A5: SYNTHETIC DEMO - NOT FOR DESIGN
A7: NOTES
A8: SYNTHETIC DATA - NOT FOR DESIGN OR CONSTRUCTION.
A9: PRELIMINARY ASCE 7-22 ELF calculation. Engineer must confirm ELF eligibility (Table 12.6-1), all inputs, and system selection. Not a structural analysis.
A10: Irregularities, redundancy, 12.2.5.4 height increases and vertical distribution are not checked.
A12: WARNINGS (generated at export - not updated by Excel edits)
A13: SDC computed from Tables 11.6-1/11.6-2 without the Section 11.6 exception (conservative).
A14: X: analysis period 1.2 s capped at Cu*Ta = 1.037 s (Section 12.8.2). Drift per 12.8.6.2 may use the analysis period.
A16: X: Single system. | Period: Cu*Ta cap (analysis T = 1.2 s exceeds Cu*Ta) | 12.8.1.3: Not requested
A17: Y: Single system. | Period: Ta (no analysis period provided) | 12.8.1.3: Not requested

Sheet Table 12.2-1
A1: ID | B1: Category | C1: System | D1: System footnotes | E1: Detailing sections | F1: R | G1: Omega0 | H1: Cd | I1: SDC B | J1: SDC C | K1: SDC D | L1: SDC E | M1: SDC F | N1: Other footnotes
A2: A1 | B2: A. BEARING WALL SYSTEMS | C2: Special reinforced concrete shear walls | D2: g, h | E2: 14.2 | F2: 5 | G2: 2.5 | H2: 5 | I2: NL | J2: NL | K2: 160 | L2: 160 | M2: 100
A3: A2 | B3: A. BEARING WALL SYSTEMS | C3: Reinforced concrete ductile coupled walls | D3: q | E3: 14.2 | F3: 8 | G3: 2.5 | H3: 8 | I3: NL | J3: NL | K3: 160 | L3: 160 | M3: 100
A4: A3 | B4: A. BEARING WALL SYSTEMS | C4: Ordinary reinforced concrete shear walls | D4: g | E4: 14.2 | F4: 4 | G4: 2.5 | H4: 4 | I4: NL | J4: NL | K4: NP | L4: NP | M4: NP
A5: A4 | B5: A. BEARING WALL SYSTEMS | C5: Detailed plain concrete shear walls | D5: g | E5: 14.2 | F5: 2 | G5: 2.5 | H5: 2 | I5: NL | J5: NP | K5: NP | L5: NP | M5: NP
A6: A5 | B6: A. BEARING WALL SYSTEMS | C6: Ordinary plain concrete shear walls | D6: g | E6: 14.2 | F6: 1.5 | G6: 2.5 | H6: 1.5 | I6: NL | J6: NP | K6: NP | L6: NP | M6: NP
A7: A6 | B7: A. BEARING WALL SYSTEMS | C7: Intermediate precast shear walls | D7: g | E7: 14.2 | F7: 4 | G7: 2.5 | H7: 4 | I7: NL | J7: NL | K7: 40 | L7: 40 | M7: 40 | N7: D, E, F: i
A8: A7 | B8: A. BEARING WALL SYSTEMS | C8: Ordinary precast shear walls | D8: g | E8: 14.2 | F8: 3 | G8: 2.5 | H8: 3 | I8: NL | J8: NP | K8: NP | L8: NP | M8: NP
A9: A8 | B9: A. BEARING WALL SYSTEMS | C9: Special reinforced masonry shear walls | E9: 14.4 | F9: 5 | G9: 2.5 | H9: 3.5 | I9: NL | J9: NL | K9: 160 | L9: 160 | M9: 100
A10: A9 | B10: A. BEARING WALL SYSTEMS | C10: Intermediate reinforced masonry shear walls | E10: 14.4 | F10: 3.5 | G10: 2.5 | H10: 2.25 | I10: NL | J10: NL | K10: NP | L10: NP | M10: NP
A11: A10 | B11: A. BEARING WALL SYSTEMS | C11: Ordinary reinforced masonry shear walls | E11: 14.4 | F11: 2 | G11: 2.5 | H11: 1.75 | I11: NL | J11: 160 | K11: NP | L11: NP | M11: NP
A12: A11 | B12: A. BEARING WALL SYSTEMS | C12: Detailed plain masonry shear walls | E12: 14.4 | F12: 2 | G12: 2.5 | H12: 1.75 | I12: NL | J12: NP | K12: NP | L12: NP | M12: NP
A13: A12 | B13: A. BEARING WALL SYSTEMS | C13: Ordinary plain masonry shear walls | E13: 14.4 | F13: 1.5 | G13: 2.5 | H13: 1.25 | I13: NL | J13: NP | K13: NP | L13: NP | M13: NP
A14: A13 | B14: A. BEARING WALL SYSTEMS | C14: Prestressed masonry shear walls | E14: 14.4 | F14: 1.5 | G14: 2.5 | H14: 1.75 | I14: NL | J14: NP | K14: NP | L14: NP | M14: NP
A15: A14 | B15: A. BEARING WALL SYSTEMS | C15: Ordinary reinforced AAC masonry shear walls | E15: 14.4 | F15: 2 | G15: 2.5 | H15: 2 | I15: NL | J15: 35 | K15: NP | L15: NP | M15: NP
A16: A15 | B16: A. BEARING WALL SYSTEMS | C16: Ordinary plain AAC masonry shear walls | E16: 14.4 | F16: 1.5 | G16: 2.5 | H16: 1.5 | I16: NL | J16: NP | K16: NP | L16: NP | M16: NP
A17: A16 | B17: A. BEARING WALL SYSTEMS | C17: Light-frame (wood) walls sheathed with wood structural panels rated for shear resistance | E17: 14.5 | F17: 6.5 | G17: 3 | H17: 4 | I17: NL | J17: NL | K17: 65 | L17: 65 | M17: 65
A18: A17 | B18: A. BEARING WALL SYSTEMS | C18: Light-frame (cold-formed steel) walls sheathed with wood structural panels rated for shear resistance or steel sheets | E18: 14.1 | F18: 6.5 | G18: 3 | H18: 4 | I18: NL | J18: NL | K18: 65 | L18: 65 | M18: 65
A19: A18 | B19: A. BEARING WALL SYSTEMS | C19: Light-frame walls with shear panels of all other materials | E19: 14.1 and 14.5 | F19: 2 | G19: 2.5 | H19: 2 | I19: NL | J19: NL | K19: 35 | L19: NP | M19: NP
A20: A19 | B20: A. BEARING WALL SYSTEMS | C20: Light-frame (cold-formed steel) wall systems using flat strap bracing | E20: 14.1 | F20: 4 | G20: 2 | H20: 3.5 | I20: NL | J20: NL | K20: 65 | L20: 65 | M20: 65
A21: A20 | B21: A. BEARING WALL SYSTEMS | C21: Cross-laminated timber shear walls | E21: 14.5 | F21: 3 | G21: 3 | H21: 3 | I21: 65 | J21: 65 | K21: 65 | L21: 65 | M21: 65
A22: A21 | B22: A. BEARING WALL SYSTEMS | C22: Cross-laminated timber shear walls with shear resistance provided by high-aspect-ratio panels only | E22: 14.5 | F22: 4 | G22: 3 | H22: 4 | I22: 65 | J22: 65 | K22: 65 | L22: 65 | M22: 65
A23: B1 | B23: B. BUILDING FRAME SYSTEMS | C23: Steel eccentrically braced frames | E23: 14.1 | F23: 8 | G23: 2 | H23: 4 | I23: NL | J23: NL | K23: 160 | L23: 160 | M23: 100
A24: B2 | B24: B. BUILDING FRAME SYSTEMS | C24: Steel special concentrically braced frames | E24: 14.1 | F24: 6 | G24: 2 | H24: 5 | I24: NL | J24: NL | K24: 160 | L24: 160 | M24: 100
A25: B3 | B25: B. BUILDING FRAME SYSTEMS | C25: Steel ordinary concentrically braced frames | E25: 14.1 | F25: 3.25 | G25: 2 | H25: 3.25 | I25: NL | J25: NL | K25: 35 | L25: 35 | M25: NP | N25: D, E, F: j
A26: B4 | B26: B. BUILDING FRAME SYSTEMS | C26: Special reinforced concrete shear walls | D26: g, h | E26: 14.2 | F26: 6 | G26: 2.5 | H26: 5 | I26: NL | J26: NL | K26: 160 | L26: 160 | M26: 100
A27: B5 | B27: B. BUILDING FRAME SYSTEMS | C27: Reinforced concrete ductile coupled walls | D27: q | E27: 14.2 | F27: 8 | G27: 2.5 | H27: 8 | I27: NL | J27: NL | K27: 160 | L27: 160 | M27: 100
A28: B6 | B28: B. BUILDING FRAME SYSTEMS | C28: Ordinary reinforced concrete shear walls | D28: g | E28: 14.2 | F28: 5 | G28: 2.5 | H28: 4.5 | I28: NL | J28: NL | K28: NP | L28: NP | M28: NP
A29: B7 | B29: B. BUILDING FRAME SYSTEMS | C29: Detailed plain concrete shear walls | D29: g | E29: 14.2 and 14.2.2.7 | F29: 2 | G29: 2.5 | H29: 2 | I29: NL | J29: NP | K29: NP | L29: NP | M29: NP
A30: B8 | B30: B. BUILDING FRAME SYSTEMS | C30: Ordinary plain concrete shear walls | D30: g | E30: 14.2 | F30: 1.5 | G30: 2.5 | H30: 1.5 | I30: NL | J30: NP | K30: NP | L30: NP | M30: NP
A31: B9 | B31: B. BUILDING FRAME SYSTEMS | C31: Intermediate precast shear walls | D31: g | E31: 14.2 | F31: 5 | G31: 2.5 | H31: 4.5 | I31: NL | J31: NL | K31: 40 | L31: 40 | M31: 40 | N31: D, E, F: i
A32: B10 | B32: B. BUILDING FRAME SYSTEMS | C32: Ordinary precast shear walls | D32: g | E32: 14.2 | F32: 4 | G32: 2.5 | H32: 4 | I32: NL | J32: NP | K32: NP | L32: NP | M32: NP
A33: B11 | B33: B. BUILDING FRAME SYSTEMS | C33: Steel and concrete composite eccentrically braced frames | E33: 14.3 | F33: 8 | G33: 2.5 | H33: 4 | I33: NL | J33: NL | K33: 160 | L33: 160 | M33: 100
A34: B12 | B34: B. BUILDING FRAME SYSTEMS | C34: Steel and concrete composite special concentrically braced frames | E34: 14.3 | F34: 5 | G34: 2 | H34: 4.5 | I34: NL | J34: NL | K34: 160 | L34: 160 | M34: 100
A35: B13 | B35: B. BUILDING FRAME SYSTEMS | C35: Steel and concrete composite ordinary braced frames | E35: 14.3 | F35: 3 | G35: 2 | H35: 3 | I35: NL | J35: NL | K35: NP | L35: NP | M35: NP
A36: B14 | B36: B. BUILDING FRAME SYSTEMS | C36: Steel and concrete composite plate shear walls | E36: 14.3 | F36: 6.5 | G36: 2.5 | H36: 5.5 | I36: NL | J36: NL | K36: 160 | L36: 160 | M36: 100
A37: B15 | B37: B. BUILDING FRAME SYSTEMS | C37: Steel and concrete composite special shear walls | E37: 14.3 | F37: 6 | G37: 2.5 | H37: 5 | I37: NL | J37: NL | K37: 160 | L37: 160 | M37: 100
A38: B16 | B38: B. BUILDING FRAME SYSTEMS | C38: Steel and concrete composite ordinary shear walls | E38: 14.3 | F38: 5 | G38: 2.5 | H38: 4.5 | I38: NL | J38: NL | K38: NP | L38: NP | M38: NP
A39: B17 | B39: B. BUILDING FRAME SYSTEMS | C39: Special reinforced masonry shear walls | E39: 14.4 | F39: 5.5 | G39: 2.5 | H39: 4 | I39: NL | J39: NL | K39: 160 | L39: 160 | M39: 100
A40: B18 | B40: B. BUILDING FRAME SYSTEMS | C40: Intermediate reinforced masonry shear walls | E40: 14.4 | F40: 4 | G40: 2.5 | H40: 4 | I40: NL | J40: NL | K40: NP | L40: NP | M40: NP
...

Sheet Code Tables
A1: ASCE 7-22 LOOKUP TABLES (PRELIMINARY)
A4: Table 1.5-2 - Risk Category | B4: Ie
A5: I | B5: 1
A6: II | B6: 1
A7: III | B7: 1.25
A8: IV | B8: 1.5
A10: Table 12.8-2 - type key | B10: Description | C10: Ct | D10: x
A11: steel_mf | B11: Steel moment-resisting frames | C11: 0.028 | D11: 0.8
A12: concrete_mf | B12: Concrete moment-resisting frames | C12: 0.016 | D12: 0.9
A13: steel_ebf | B13: Steel eccentrically braced frames (B1/D1) | C13: 0.03 | D13: 0.75
A14: steel_brbf | B14: Steel buckling-restrained braced frames (B26/D13) | C14: 0.03 | D14: 0.75
A15: all_other | B15: All other structural systems | C15: 0.02 | D15: 0.75
A17: Section 12.8.1.3 max SDS for Cs | B17: 1
A18: Cap value verified against ASCE 7-22? | B18: NO - VERIFY
A21: Table 12.8-1 - SD1 (g) | B21: Cu
A22: 0.4 | B22: 1.4
A23: 0.3 | B23: 1.4
A24: 0.2 | B24: 1.5
A25: 0.15 | B25: 1.6
A26: 0.1 | B26: 1.7
A27: Cu is linearly interpolated between rows; constant beyond the end rows.
